<?xml version='1.0' encoding='utf-8'?>
<robot name="hi_cl">

	<gazebo>
		<plugin name="gazebo_ros_control" filename="libhi_bipedal_hw_sim.so">
		<robotNamespace>/</robotNamespace>
		<robotParam>legged_robot_description</robotParam>
		<robotSimType>hi_gazebo/hiHWSim</robotSimType>
		</plugin>
	</gazebo>

	<gazebo>
		<plugin filename="libgazebo_ros_p3d.so" name="p3d_base_controller">
		<alwaysOn>true</alwaysOn>
		<updateRate>500.0</updateRate>
		<bodyName>base_link</bodyName>
		<topicName>ground_truth/state</topicName>
		<gaussianNoise>0</gaussianNoise>
		<frameName>world</frameName>
		<xyzOffsets>0 0 0</xyzOffsets>
		<rpyOffsets>0 0 0</rpyOffsets>
		</plugin>
	</gazebo>	

	<link name="base_link">
		<inertial>
			<origin xyz="-0.00154853 -7.263E-05 -0.0269642" rpy="0 0 0" />
			<mass value="4" />
			<inertia ixx="0.00957622" ixy="1.02E-06" ixz="-8.442E-05" iyy="0.00654424" iyz="1.11E-06" izz="0.00526567" />
		</inertial>
		<visual>
			<origin xyz="0 0 0" rpy="0 0 0" />
			<geometry>
				<mesh filename="package://hi_description/meshes/base_link.STL" />
			</geometry>
			<material name="">
				<color rgba="0.79216 0.81961 0.93333 1" />
			</material>
		</visual>
		<collision>
			<origin xyz="0 0 0" rpy="0 0 0" />
			<geometry>
				<box size="0.03 0.03 0.03" />
			</geometry>
		</collision>
	</link>

  	<joint name="imu_joint" type="fixed">
      <origin rpy="0. 0. 0." xyz="0. 0. 0" />
      <parent link="base_link" />
      <child link="imu_link" />
    </joint>
    
    <link name="imu_link">
      <inertial>
        <mass value="0.01" />
        <origin rpy="0 0 0" xyz="0 0 0" />
        <inertia ixx="0.000001" ixy="0" ixz="0" iyy="0.000001" iyz="0" izz="0.000001" />
      </inertial>
      <visual>
        <origin rpy="0 0 0" xyz="0 0 0" />
        <geometry>
          <box size="0.015 0.015 0.004" />
        </geometry>
      </visual>
      <material name="orange">
        <color rgba="255 108 10 255" />
      </material>
    </link>
    <gazebo reference="imu_joint">
      <disableFixedJointLumping>true</disableFixedJointLumping>
    </gazebo>	


	<link name="r_shoulder_pitch_link">
		<inertial>
			<origin xyz="-0.028075102 -0.066132919 0.010310958" rpy="0 0 0" />
			<mass value="0.49941784" />
			<inertia ixx="0.021546731" ixy="-6.3892519e-08" ixz="-3.3802334e-05" iyy="0.021546708" iyz="-4.0731029e-05" izz="1.3057332e-07" />
		</inertial>
		<visual>
			<origin xyz="0 0 0" rpy="0 0 0" />
			<geometry>
				<mesh filename="package://hi_description/meshes/r_shoulder_pitch_link.STL" />
			</geometry>
			<material name="">
				<color rgba="0.89804 0.91765 0.92941 1" />
			</material>
		</visual>
		<collision>
			<origin xyz="0 0 0" rpy="0 0 0" />
			<geometry>
				<box size="0.01 0.01 0.01" />
			</geometry>
		</collision>
	</link>
	<joint name="r_shoulder_pitch_joint" type="revolute">
		<origin xyz="0 -0.08085 0" rpy="0 0 0" />
		<parent link="base_link" />
		<child link="r_shoulder_pitch_link" />
		<axis xyz="0 1 0" />
		<limit lower="-3.14" upper="3.14" effort="36" velocity="21" />
	<dynamics damping="1.3328433e-07" friction="0.15531231" /></joint>

	<link name="r_shoulder_roll_link">
		<inertial>
			<origin xyz="-0.025318239 0.0028018554 0.010666805" rpy="0 0 0" />
			<mass value="0.3" />
			<inertia ixx="0.025167717" ixy="-0.0075180554" ixz="-0.0029049849" iyy="0.0058506152" iyz="-0.0084614851" izz="0.024479278" />
		</inertial>
		<visual>
			<origin xyz="0 0 0" rpy="0 0 0" />
			<geometry>
				<mesh filename="package://hi_description/meshes/r_shoulder_roll_link.STL" />
			</geometry>
			<material name="">
				<color rgba="0.89804 0.91765 0.92941 1" />
			</material>
		</visual>
		<collision>
			<origin xyz="0 0 0" rpy="0 0 0" />
			<geometry>
				<box size="0.01 0.01 0.01" />
			</geometry>
		</collision>
	</link>
	<joint name="r_shoulder_roll_joint" type="revolute">
		<origin xyz="0 -0.06515 0" rpy="0 0 0" />
		<parent link="r_shoulder_pitch_link" />
		<child link="r_shoulder_roll_link" />
		<axis xyz="1 0 0" />
		<limit lower="-3.14" upper="3.14" effort="36" velocity="21" />
	<dynamics damping="0.26549139" friction="0.055312309" /></joint>

	<link name="r_arm_yaw_link">
		<inertial>
			<origin xyz="-0.013496499 0.016478683 -0.030281392" rpy="0 0 0" />
			<mass value="0.3" />
			<inertia ixx="0.018327572" ixy="0.0060882989" ixz="-0.0013851756" iyy="0.0030291789" iyz="0.0039645692" izz="0.019552758" />
		</inertial>
		<visual>
			<origin xyz="0 0 0" rpy="0 0 0" />
			<geometry>
				<mesh filename="package://hi_description/meshes/r_arm_yaw_link.STL" />
			</geometry>
			<material name="">
				<color rgba="0.89804 0.91765 0.92941 1" />
			</material>
		</visual>
		<collision>
			<origin xyz="0 0 0" rpy="0 0 0" />
			<geometry>
				<box size="0.01 0.01 0.01" />
			</geometry>
		</collision>
	</link>
	<joint name="r_arm_yaw_joint" type="revolute">
		<origin xyz="-0.0026 0 -0.06495" rpy="0 0 1.5707963" />
		<parent link="r_shoulder_roll_link" />
		<child link="r_arm_yaw_link" />
		<axis xyz="0 0 1" />
		<limit lower="-3.14" upper="3.14" effort="36" velocity="21" />
	<dynamics damping="0.067926697" friction="0.098291677" /></joint>

	<link name="r_arm_roll_link">
		<inertial>
			<origin xyz="0.025318238 -0.0028018562 0.010666805" rpy="0 0 0" />
			<mass value="0.3" />
			<inertia ixx="0.025167717" ixy="-0.0075180554" ixz="0.0029049849" iyy="0.0058506152" iyz="0.0084614851" izz="0.024479278" />
		</inertial>
		<visual>
			<origin xyz="0 0 0" rpy="0 0 0" />
			<geometry>
				<mesh filename="package://hi_description/meshes/r_arm_roll_link.STL" />
			</geometry>
			<material name="">
				<color rgba="0.89804 0.91765 0.92941 1" />
			</material>
		</visual>
		<collision>
			<origin xyz="0 0 0" rpy="0 0 0" />
			<geometry>
				<box size="0.01 0.01 0.01" />
			</geometry>
		</collision>
	</link>
	<joint name="r_arm_roll_joint" type="revolute">
		<origin xyz="0 0 -0.06645" rpy="-1.5707963 0 0" />
		<parent link="r_arm_yaw_link" />
		<child link="r_arm_roll_link" />
		<axis xyz="1 0 0" />
		<limit lower="-3.14" upper="3.14" effort="36" velocity="21" />
	<dynamics damping="0.30000013" friction="0.11060222" /></joint>

	<link name="r_wrist_yaw_link">
		<inertial>
			<origin xyz="-0.0057260345 0.00079569477 -0.022009393" rpy="0 0 0" />
			<mass value="0.07" />
			<inertia ixx="0.012406076" ixy="0.012311429" ixz="-0.0051339458" iyy="0.016179829" iyz="0.0044070524" izz="0.024910367" />
		</inertial>
		<visual>
			<origin xyz="0 0 0" rpy="0 0 0" />
			<geometry>
				<mesh filename="package://hi_description/meshes/r_wrist_yaw_link.STL" />
			</geometry>
			<material name="">
				<color rgba="0.49804 0.49804 0.49804 1" />
			</material>
		</visual>
		<collision>
			<origin xyz="0 0 0" rpy="0 0 0" />
			<geometry>
				<mesh filename="file:///home/x/biped_ws/src/hi_dynamic_control/hi_examples/hi_biped/hi_description/meshes/r_wrist_yaw_link.STL" />
			</geometry>
		</collision>
	</link>
	<joint name="r_wrist_yaw_joint" type="revolute">
		<origin xyz="0.0026 0 -0.06495" rpy="0 0 0" />
		<parent link="r_arm_roll_link" />
		<child link="r_wrist_yaw_link" />
		<axis xyz="0 0 1" />
		<limit lower="-3.14" upper="3.14" effort="36" velocity="21" />
	<dynamics damping="0.13751436" friction="0.050311789" /></joint>

	
	<link name="r_hand_box_link">
		<inertial>
			<origin xyz="0.0 0 0" rpy="0 0 0" />
			<mass value="0.01" />
			<inertia ixx="0.0005" ixy="0" ixz="0" iyy="0.001" iyz="0" izz="0.001" />
		</inertial>
		<visual>
			<origin xyz="0.0 0 0" rpy="0 0 0" />
			<geometry>
				<box size="0.06 0.06 0.02" />
			</geometry>
			<material name="">
				<color rgba="0.3 0.3 0.3 1" />
			</material>
		</visual>
		<collision>
			<origin xyz="0.0 0 0" rpy="0 0 0" />
			<geometry>
				<box size="0.06 0.06 0.02" />
			</geometry>
		</collision>
	</link>

	<joint name="r_hand_box_joint" type="fixed">
		<origin xyz="0 0 -0.085" rpy="0 0 0" />  
		<parent link="r_wrist_yaw_link" />
		<child link="r_hand_box_link" />
	</joint>

	<gazebo reference="r_hand_box_link">
		<mu1>1.0</mu1>  
		<mu2>1.0</mu2>
		<kp value="1000000.0" />
		<kd value="100.0" />
	</gazebo>
	

	
	<gazebo reference="r_wrist_yaw_joint">
	<provideFeedback>true</provideFeedback>
	</gazebo>

	<gazebo>
	<plugin name="ft_sensor_right_wrist" filename="libgazebo_ros_ft_sensor.so">
		<updateRate>500.0</updateRate>
		<topicName>right_wrist_ft_sensor</topicName>
		<jointName>r_wrist_yaw_joint</jointName>
	</plugin>
	</gazebo>

	
    <transmission name="r_shoulder_pitch_tran">
        <type>transmission_interface/SimpleTransmission</type>
        <joint name="r_shoulder_pitch_joint">
            <hardwareInterface>hardware_interface/EffortJointInterface</hardwareInterface>
        </joint>
        <actuator name="r_shoulder_pitch_motor">
            <hardwareInterface>hardware_interface/EffortJointInterface</hardwareInterface>
            <mechanicalReduction>1</mechanicalReduction>
        </actuator>
    </transmission>
    
    <transmission name="r_shoulder_roll_tran">
        <type>transmission_interface/SimpleTransmission</type>
        <joint name="r_shoulder_roll_joint">
            <hardwareInterface>hardware_interface/EffortJointInterface</hardwareInterface>
        </joint>
        <actuator name="r_shoulder_roll_motor">
            <hardwareInterface>hardware_interface/EffortJointInterface</hardwareInterface>
            <mechanicalReduction>1</mechanicalReduction>
        </actuator>
    </transmission>
    
    <transmission name="r_arm_yaw_tran">
        <type>transmission_interface/SimpleTransmission</type>
        <joint name="r_arm_yaw_joint">
            <hardwareInterface>hardware_interface/EffortJointInterface</hardwareInterface>
        </joint>
        <actuator name="r_arm_yaw_motor">
            <hardwareInterface>hardware_interface/EffortJointInterface</hardwareInterface>
            <mechanicalReduction>1</mechanicalReduction>
        </actuator>
    </transmission>
    
    <transmission name="r_arm_roll_tran">
        <type>transmission_interface/SimpleTransmission</type>
        <joint name="r_arm_roll_joint">
            <hardwareInterface>hardware_interface/EffortJointInterface</hardwareInterface>
        </joint>
        <actuator name="r_arm_roll_motor">
            <hardwareInterface>hardware_interface/EffortJointInterface</hardwareInterface>
            <mechanicalReduction>1</mechanicalReduction>
        </actuator>
    </transmission>
    
    <transmission name="r_wrist_yaw_tran">
        <type>transmission_interface/SimpleTransmission</type>
        <joint name="r_wrist_yaw_joint">
            <hardwareInterface>hardware_interface/EffortJointInterface</hardwareInterface>
        </joint>
        <actuator name="r_wrist_yaw_motor">
            <hardwareInterface>hardware_interface/EffortJointInterface</hardwareInterface>
            <mechanicalReduction>1</mechanicalReduction>
        </actuator>
    </transmission>



	<link name="l_shoulder_pitch_link">
		<inertial>
			<origin xyz="0.00095302 0.058734 -8.0741E-05" rpy="0 0 0" />
			<mass value="0.35" />
			<inertia ixx="0.00016981" ixy="1.582E-05" ixz="-6E-08" iyy="0.00014053" iyz="7.3E-07" izz="0.00020608" />
		</inertial>
		<visual>
			<origin xyz="0 0 0" rpy="0 0 0" />
			<geometry>
				<mesh filename="package://hi_description/meshes/l_shoulder_pitch_link.STL" />
			</geometry>
			<material name="">
				<color rgba="1 1 1 1" />
			</material>
		</visual>
		<collision>
			<origin xyz="0 0 0" rpy="0 0 0" />
			<geometry>
				<box size="0.01 0.01 0.01" />
			</geometry>
		</collision>
	</link>
	<joint name="l_shoulder_pitch_joint" type="revolute">
		<origin xyz="0 0.08085 0" rpy="0 0 0" />
		<parent link="base_link" />
		<child link="l_shoulder_pitch_link" />
		<axis xyz="0 1 0" />
		<limit lower="-3.14" upper="3.14" effort="36" velocity="21" />
	</joint>

	<link name="l_shoulder_roll_link">
		<inertial>
			<origin xyz="-0.0088047 8.879E-05 -0.052824" rpy="0 0 0" />
			<mass value="0.35" />
			<inertia ixx="0.00028497" ixy="4.1E-07" ixz="8.018E-05" iyy="0.00032147" iyz="3.6E-07" izz="0.00014121" />
		</inertial>
		<visual>
			<origin xyz="0 0 0" rpy="0 0 0" />
			<geometry>
				<mesh filename="package://hi_description/meshes/l_shoulder_roll_link.STL" />
			</geometry>
			<material name="">
				<color rgba="0.89804 0.91765 0.92941 1" />
			</material>
		</visual>
		<collision>
			<origin xyz="0 0 0" rpy="0 0 0" />
			<geometry>
				<box size="0.01 0.01 0.01" />
			</geometry>
		</collision>
	</link>
	<joint name="l_shoulder_roll_joint" type="revolute">
		<origin xyz="0 0.06515 0" rpy="0 0 0" />
		<parent link="l_shoulder_pitch_link" />
		<child link="l_shoulder_roll_link" />
		<axis xyz="1 0 0" />
		<limit lower="-3.14" upper="3.14" effort="36" velocity="21" />
	</joint>

	<link name="l_arm_yaw_link">
		<inertial>
			<origin xyz="-0.002422 8.6807E-05 -0.059552" rpy="0 0 0" />
			<mass value="0.35" />
			<inertia ixx="0.00017393" ixy="-1.1E-07" ixz="1.346E-05" iyy="0.00020583" iyz="8E-07" izz="0.00013651" />
		</inertial>
		<visual>
			<origin xyz="0 0 0" rpy="0 0 0" />
			<geometry>
				<mesh filename="package://hi_description/meshes/l_arm_yaw_link.STL" />
			</geometry>
			<material name="">
				<color rgba="0.89804 0.91765 0.92941 1" />
			</material>
		</visual>
		<collision>
			<origin xyz="0 0 0" rpy="0 0 0" />
			<geometry>
				<box size="0.01 0.01 0.01" />
			</geometry>
		</collision>
	</link>
	<joint name="l_arm_yaw_joint" type="revolute">
		<origin xyz="-0.0026 0 -0.06495" rpy="0 0 1.5707963" />
		<parent link="l_shoulder_roll_link" />
		<child link="l_arm_yaw_link" />
		<axis xyz="0 0 1" />
		<limit lower="-3.14" upper="3.14" effort="36" velocity="21" />
	</joint>

	<link name="l_arm_roll_link">
		<inertial>
			<origin xyz="0.0088047 -8.879E-05 -0.052824" rpy="0 0 0" />
			<mass value="0.35" />
			<inertia ixx="0.00028497" ixy="4.1E-07" ixz="-8.018E-05" iyy="0.00032147" iyz="-3.6E-07" izz="0.00014121" />
		</inertial>
		<visual>
			<origin xyz="0 0 0" rpy="0 0 0" />
			<geometry>
				<mesh filename="package://hi_description/meshes/l_arm_roll_link.STL" />
			</geometry>
			<material name="">
				<color rgba="0.89804 0.91765 0.92941 1" />
			</material>
		</visual>
		<collision>
			<origin xyz="0 0 0" rpy="0 0 0" />
			<geometry>
				<box size="0.01 0.01 0.01" />
			</geometry>
		</collision>
	</link>
	<joint name="l_arm_roll_joint" type="revolute">
		<origin xyz="0 0 -0.06645" rpy="-1.5707963 0 0" />
		<parent link="l_arm_yaw_link" />
		<child link="l_arm_roll_link" />
		<axis xyz="1 0 0" />
		<limit lower="-3.14" upper="3.14" effort="36" velocity="21" />
	</joint>

	<link name="l_wrist_yaw_link">
		<inertial>
			<origin xyz="1.1102E-16 3.7151E-14 -0.06558" rpy="0 0 0" />
			<mass value="0.035143" />
			<inertia ixx="1.2175E-05" ixy="2.3882E-22" ixz="2.2238E-20" iyy="1.2175E-05" iyz="3.9298E-20" izz="3.7315E-06" />
		</inertial>
		<visual>
			<origin xyz="0 0 0" rpy="0 0 0" />
			<geometry>
				<mesh filename="package://hi_description/meshes/l_wrist_yaw_link.STL" />
			</geometry>
			<material name="">
				<color rgba="0.49804 0.49804 0.49804 1" />
			</material>
		</visual>
		<collision>
			<origin xyz="0 0 0" rpy="0 0 0" />
			<geometry>
				<mesh filename="file:///home/x/biped_ws/src/hi_dynamic_control/hi_examples/hi_biped/hi_description/meshes/l_wrist_yaw_link.STL" />
			</geometry>
		</collision>
	</link>
	<joint name="l_wrist_yaw_joint" type="revolute">
		<origin xyz="0.0026 0 -0.06495" rpy="0 0 0" />
		<parent link="l_arm_roll_link" />
		<child link="l_wrist_yaw_link" />
		<axis xyz="0 0 1" />
		<limit lower="-3.14" upper="3.14" effort="36" velocity="21" />
	</joint>


	
	<link name="l_hand_box_link">
		<inertial>
			<origin xyz="0.0 0 0" rpy="0 0 0" />
			<mass value="0.01" />
			<inertia ixx="0.0005" ixy="0" ixz="0" iyy="0.001" iyz="0" izz="0.001" />
		</inertial>
		<visual>
			<origin xyz="0.0 0 0" rpy="0 0 0" />
			<geometry>
				<box size="0.06 0.06 0.02" />
			</geometry>
			<material name="">
				<color rgba="0.3 0.3 0.3 1" />
			</material>
		</visual>
		<collision>
			<origin xyz="0.0 0 0" rpy="0 0 0" />
			<geometry>
				<box size="0.06 0.06 0.02" />
			</geometry>
		</collision>
	</link>

	<joint name="l_hand_box_joint" type="fixed">
		<origin xyz="0 0 -0.085" rpy="0 0 0" />  
		<parent link="l_wrist_yaw_link" />
		<child link="l_hand_box_link" />
	</joint>

	<gazebo reference="l_hand_box_link">
		<mu1>1.0</mu1>  
		<mu2>1.0</mu2>
		<kp value="1000000.0" />
		<kd value="100.0" />
	</gazebo>
	

	
	<gazebo reference="l_wrist_yaw_joint">
	<provideFeedback>true</provideFeedback>
	</gazebo>

	<gazebo>
	<plugin name="ft_sensor_left_wrist" filename="libgazebo_ros_ft_sensor.so">
		<updateRate>500.0</updateRate>
		<topicName>left_wrist_ft_sensor</topicName>
		<jointName>l_wrist_yaw_joint</jointName>
	</plugin>
	</gazebo>

	
    <transmission name="l_shoulder_pitch_tran">
        <type>transmission_interface/SimpleTransmission</type>
        <joint name="l_shoulder_pitch_joint">
            <hardwareInterface>hardware_interface/EffortJointInterface</hardwareInterface>
        </joint>
        <actuator name="l_shoulder_pitch_motor">
            <hardwareInterface>hardware_interface/EffortJointInterface</hardwareInterface>
            <mechanicalReduction>1</mechanicalReduction>
        </actuator>
    </transmission>
    
    <transmission name="l_shoulder_roll_tran">
        <type>transmission_interface/SimpleTransmission</type>
        <joint name="l_shoulder_roll_joint">
            <hardwareInterface>hardware_interface/EffortJointInterface</hardwareInterface>
        </joint>
        <actuator name="l_shoulder_roll_motor">
            <hardwareInterface>hardware_interface/EffortJointInterface</hardwareInterface>
            <mechanicalReduction>1</mechanicalReduction>
        </actuator>
    </transmission>
    
    <transmission name="l_arm_yaw_tran">
        <type>transmission_interface/SimpleTransmission</type>
        <joint name="l_arm_yaw_joint">
            <hardwareInterface>hardware_interface/EffortJointInterface</hardwareInterface>
        </joint>
        <actuator name="l_arm_yaw_motor">
            <hardwareInterface>hardware_interface/EffortJointInterface</hardwareInterface>
            <mechanicalReduction>1</mechanicalReduction>
        </actuator>
    </transmission>
    
    <transmission name="l_arm_roll_tran">
        <type>transmission_interface/SimpleTransmission</type>
        <joint name="l_arm_roll_joint">
            <hardwareInterface>hardware_interface/EffortJointInterface</hardwareInterface>
        </joint>
        <actuator name="l_arm_roll_motor">
            <hardwareInterface>hardware_interface/EffortJointInterface</hardwareInterface>
            <mechanicalReduction>1</mechanicalReduction>
        </actuator>
    </transmission>
    
    <transmission name="l_wrist_yaw_tran">
        <type>transmission_interface/SimpleTransmission</type>
        <joint name="l_wrist_yaw_joint">
            <hardwareInterface>hardware_interface/EffortJointInterface</hardwareInterface>
        </joint>
        <actuator name="l_wrist_yaw_motor">
            <hardwareInterface>hardware_interface/EffortJointInterface</hardwareInterface>
            <mechanicalReduction>1</mechanicalReduction>
        </actuator>
    </transmission>


	<link name="loin_yaw_link">
		<inertial>
			<origin xyz="0 0 -0.060242" rpy="0 0 0" />
			<mass value="1.305" />
			<inertia ixx="0.0015765" ixy="2.98E-06" ixz="0" iyy="0.00041876" iyz="0" izz="0.0014561" />
		</inertial>
		<visual>
			<origin xyz="0 0 0" rpy="0 0 0" />
			<geometry>
				<mesh filename="package://hi_description/meshes/loin_yaw_link.STL" />
			</geometry>
			<material name="">
				<color rgba="1 1 1 1" />
			</material>
		</visual>
		<collision>
			<origin xyz="0 0 0" rpy="0 0 0" />
			<geometry>
				<box size="0.01 0.01 0.01" />
			</geometry>
		</collision>
	</link>
	<joint name="loin_yaw_joint" type="fixed">
		<origin xyz="0 0 -0.19425" rpy="0 0 0" />
		<parent link="base_link" />
		<child link="loin_yaw_link" />
		<axis xyz="0 0 1" />
		<limit lower="-3.14" upper="3.14" effort="36" velocity="21" />
	</joint>

  
  
  	
	<link name="leg_r1_link">
		<inertial>
			<origin xyz="-0.00022626 -0.06684 9.015E-05" rpy="0 0 0" />
			<mass value="0.661" />
			<inertia ixx="0.00018617" ixy="-1E-08" ixz="1.2E-07" iyy="0.00019782" iyz="4.7E-07" izz="0.0002263" />
		</inertial>
		<visual>
			<origin xyz="0 0 0" rpy="0 0 0" />
			<geometry>
				<mesh filename="package://hi_description/meshes/r_hip_pitch_link.STL" />
			</geometry>
			<material name="">
				<color rgba="0.79216 0.81961 0.93333 1" />
			</material>
		</visual>
		<collision>
			<origin xyz="0 0 0" rpy="0 0 0" />
			<geometry>
				<box size="0.01 0.01 0.01" />
			</geometry>
		</collision>
	</link>
	<joint name="leg_r1_joint" type="revolute">
		<origin xyz="0 -0.02875 -0.06425" rpy="0 0 0" />
		<parent link="loin_yaw_link" />
		<child link="leg_r1_link" />
		<axis xyz="0 1 0" />
		<limit lower="-1.25" upper="1.75" effort="36" velocity="21" />
	</joint>

	<link name="leg_r2_link">
		<inertial>
			<origin xyz="0.00088845 -0.00019059 -0.066357" rpy="0 0 0" />
			<mass value="0.54219" />
			<inertia ixx="0.00096893" ixy="-6.4E-07" ixz="-2.26E-05" iyy="0.0012165" iyz="-2.89E-06" izz="0.0004037" />
		</inertial>
		<visual>
			<origin xyz="0 0 0" rpy="0 0 0" />
			<geometry>
				<mesh filename="package://hi_description/meshes/r_hip_roll_link.STL" />
			</geometry>
			<material name="">
				<color rgba="0.89804 0.91765 0.92941 1" />
			</material>
		</visual>
		<collision>
			<origin xyz="0 0 0" rpy="0 0 0" />
			<geometry>
				<box size="0.01 0.01 0.01" />
			</geometry>
		</collision>
	</link>
	<joint name="leg_r2_joint" type="revolute">
		<origin xyz="0 -0.06875 0" rpy="0 0 0" />
		<parent link="leg_r1_link" />
		<child link="leg_r2_link" />
		<axis xyz="1 0 0" />
		<limit lower="-0.5" upper="0.5" effort="36" velocity="21" />
	</joint>
	<link name="leg_r3_link">
		<inertial>
			<origin xyz="0 0.0019897 -0.066297" rpy="0 0 0" />
			<mass value="0.23898" />
			<inertia ixx="0.00050536" ixy="-1.1811E-12" ixz="5.2665E-11" iyy="0.00032488" iyz="1.858E-05" izz="0.00029126" />
		</inertial>
		<visual>
			<origin xyz="0 0 0" rpy="0 0 0" />
			<geometry>
				<mesh filename="package://hi_description/meshes/r_thigh_link.STL" />
			</geometry>
			<material name="">
				<color rgba="0.89804 0.91765 0.92941 1" />
			</material>
		</visual>
		<collision>
			<origin xyz="0 0 0" rpy="0 0 0" />
			<geometry>
				<box size="0.01 0.01 0.01" />
			</geometry>
		</collision>
	</link>
	<joint name="leg_r3_joint" type="revolute">
		<origin xyz="0 0 -0.09425" rpy="0 0 0" />
		<parent link="leg_r2_link" />
		<child link="leg_r3_link" />
		<axis xyz="0 0 1" />
		<limit lower="-0.6" upper="0.3" effort="36" velocity="21" />
	</joint>

	<link name="leg_r4_link">
		<inertial>
			<origin xyz="-8.965E-05 -0.0020679 -0.050651" rpy="0 0 0" />
			<mass value="1.2" />
			<inertia ixx="0.0068013" ixy="2.6E-07" ixz="-3.47E-06" iyy="0.006751" iyz="-4.2E-07" izz="0.00034715" />
		</inertial>
		<visual>
			<origin xyz="0 0 0" rpy="0 0 0" />
			<geometry>
				<mesh filename="package://hi_description/meshes/r_calf_link.STL" />
			</geometry>
			<material name="">
				<color rgba="0.79216 0.81961 0.93333 1" />
			</material>
		</visual>
		<collision>
			<origin xyz="0 0 0" rpy="0 0 0" />
			<geometry>
				<box size="0.01 0.01 0.01" />
			</geometry>
		</collision>
	</link>
	<joint name="leg_r4_joint" type="revolute">
		<origin xyz="0 0 -0.10575" rpy="0 0 0" />
		<parent link="leg_r3_link" />
		<child link="leg_r4_link" />
		<axis xyz="0 1 0" />
		<limit lower="-0.65" upper="1.65" effort="36" velocity="21" />
	</joint>

	<link name="leg_r5_link">
		<inertial>
			<origin xyz="0.0072806 0.00051939 2.2469E-12" rpy="0 0 0" />
			<mass value="0.16682" />
			<inertia ixx="0.0001187" ixy="1E-06" ixz="0" iyy="0.0001994" iyz="3.7295E-17" izz="0.00028526" />
		</inertial>
		<visual>
			<origin xyz="0 0 0" rpy="0 0 0" />
			<geometry>
				<mesh filename="package://hi_description/meshes/r_ankle_pitch_link.STL" />
			</geometry>
			<material name="">
				<color rgba="0.89804 0.91765 0.92941 1" />
			</material>
		</visual>
		<collision>
			<origin xyz="0 0 0" rpy="0 0 0" />
			<geometry>
				<box size="0.01 0.01 0.01" />
			</geometry>
		</collision>
	</link>
	<joint name="leg_r5_joint" type="revolute">
		<origin xyz="0 0 -0.2" rpy="0 0 0" />
		<parent link="leg_r4_link" />
		<child link="leg_r5_link" />
		<axis xyz="0 1 0" />
		<limit lower="-0.9" upper="0.9" effort="36" velocity="21" />
	</joint>

	<link name="leg_r6_link">
		<inertial>
			<origin xyz="-0.040001 9.312E-05 -0.023563" rpy="0 0 0" />
			<mass value="0.5" />
			<inertia ixx="0.00040772" ixy="-2.34E-06" ixz="-9.125E-05" iyy="0.0015071" iyz="-4.6E-07" izz="0.0013858" />
		</inertial>
		<visual>
			<origin xyz="0 0 0" rpy="0 0 0" />
			<geometry>
				<mesh filename="package://hi_description/meshes/r_ankle_roll_link.STL" />
			</geometry>
			<material name="">
				<color rgba="1 1 1 1" />
			</material>
		</visual>
		<collision>
			<origin xyz="0 0 0" rpy="0 0 0" />
			<geometry>
				<box size="0.01 0.01 0.01" />
			</geometry>
		</collision>
	</link>
	<joint name="leg_r6_joint" type="revolute">
		<origin xyz="0.07525 -0.0003 0" rpy="0 0 0" />
		<parent link="leg_r5_link" />
		<child link="leg_r6_link" />
		<axis xyz="1 0 0" />
		<limit lower="-0.8" upper="0.8" effort="36" velocity="21" />
	</joint>

	<joint name="leg_r5_fixed_1" type="fixed">
		<origin xyz="0.03 0.02 -0.0400" rpy="0 0 0" />
		<parent link="leg_r6_link" />
		<child link="leg_r_f1_link" />
	</joint>
	<link name="leg_r_f1_link">
		<inertial>
		<mass value="0.01" />
		<inertia ixx="0.000001" ixy="0" ixz="0" iyy="0.000001" iyz="0" izz="0.000001" />
		</inertial>
		<visual>
		<origin rpy="0 0 0" xyz="0 0 0" />
		<geometry>
			<sphere radius="0.001" />
		</geometry>
		</visual>
		<collision>
		<origin rpy="0 0 0" xyz="0 0 0" />
		<geometry>
			<sphere radius="0.001" />
		</geometry>
		</collision>
	</link>

	<joint name="leg_r5_fixed_2" type="fixed">
		<origin xyz="0.03 -0.02 -0.0400" rpy="0 0 0" />
		<parent link="leg_r6_link" />
		<child link="leg_r_f2_link" />
	</joint>
	<link name="leg_r_f2_link">
		<inertial>
		<mass value="0.01" />
		<inertia ixx="0.000001" ixy="0" ixz="0" iyy="0.000001" iyz="0" izz="0.000001" />
		</inertial>
		<visual>
		<origin rpy="0 0 0" xyz="0 0 0" />
		<geometry>
			<sphere radius="0.001" />
		</geometry>
		</visual>
		<collision>
		<origin rpy="0 0 0" xyz="0 0 0" />
		<geometry>
			<sphere radius="0.001" />
		</geometry>
		</collision>
	</link>

	<joint name="leg_r5_fixed_3" type="fixed">
		<origin xyz="-0.12 0.02 -0.0400" rpy="0 0 0" />
		<parent link="leg_r6_link" />
		<child link="leg_r_f3_link" />
	</joint>
	<link name="leg_r_f3_link">
		<inertial>
		<mass value="0.01" />
		<inertia ixx="0.000001" ixy="0" ixz="0" iyy="0.000001" iyz="0" izz="0.000001" />
		</inertial>
		<visual>
		<origin rpy="0 0 0" xyz="0 0 0" />
		<geometry>
			<sphere radius="0.001" />
		</geometry>
		</visual>
		<collision>
		<origin rpy="0 0 0" xyz="0 0 0" />
		<geometry>
			<sphere radius="0.001" />
		</geometry>
		</collision>
	</link>

	<joint name="leg_r5_fixed_4" type="fixed">
		<origin xyz="-0.12 -0.02 -0.0400" rpy="0 0 0" />
		<parent link="leg_r6_link" />
		<child link="leg_r_f4_link" />
	</joint>
	<link name="leg_r_f4_link">
		<inertial>
		<mass value="0.01" />
		<inertia ixx="0.000001" ixy="0" ixz="0" iyy="0.000001" iyz="0" izz="0.000001" />
		</inertial>
		<visual>
		<origin rpy="0 0 0" xyz="0 0 0" />
		<geometry>
			<sphere radius="0.001" />
		</geometry>
		</visual>
		<collision>
		<origin rpy="0 0 0" xyz="0 0 0" />
		<geometry>
			<sphere radius="0.001" />
		</geometry>
		</collision>
	</link>	

	<gazebo reference="leg_r1_link">
		<mu1>0.6</mu1>
		<mu2>0.6</mu2>
		<self_collide>1</self_collide>
	</gazebo>
	<gazebo reference="leg_r2_link">
		<mu1>0.6</mu1>
		<mu2>0.6</mu2>
		<self_collide>1</self_collide>
	</gazebo>
	<gazebo reference="leg_r3_link">
		<mu1>0.6</mu1>
		<mu2>0.6</mu2>
		<self_collide>1</self_collide>
	</gazebo>
	<gazebo reference="leg_r4_link">
		<mu1>0.6</mu1>
		<mu2>0.6</mu2>
		<self_collide>1</self_collide>
	</gazebo>
	<gazebo reference="leg_r5_link">
		<mu1>0.6</mu1>
		<mu2>0.6</mu2>
		<self_collide>1</self_collide>
	</gazebo>
	<gazebo reference="leg_r6_link">
		<mu1>0.6</mu1>
		<mu2>0.6</mu2>
		<self_collide>1</self_collide>
	</gazebo>
	<gazebo reference="leg_r_f1_link">
		<mu1>3.0</mu1>
		<mu2>3.0</mu2>
		<self_collide>1</self_collide>
		<kp value="1000000.0" />
		<kd value="100.0" />
		<maxVel>1.0</maxVel>
		<minDepth>0.00</minDepth>
	</gazebo>
	<gazebo reference="leg_r_f2_link">
		<mu1>3.0</mu1>
		<mu2>3.0</mu2>
		<self_collide>1</self_collide>
		<kp value="1000000.0" />
		<kd value="100.0" />
		<maxVel>1.0</maxVel>
		<minDepth>0.00</minDepth>
	</gazebo>
	<gazebo reference="leg_r_f3_link">
		<mu1>3.0</mu1>
		<mu2>3.0</mu2>
		<self_collide>1</self_collide>
		<kp value="1000000.0" />
		<kd value="100.0" />
		<maxVel>1.0</maxVel>
		<minDepth>0.00</minDepth>
	</gazebo>
	<gazebo reference="leg_r_f4_link">
		<mu1>3.0</mu1>
		<mu2>3.0</mu2>
		<self_collide>1</self_collide>
		<kp value="1000000.0" />
		<kd value="100.0" />
		<maxVel>1.0</maxVel>
		<minDepth>0.00</minDepth>
	</gazebo>

    <transmission name="leg_r1_tran">
        <type>transmission_interface/SimpleTransmission</type>
        <joint name="leg_r1_joint">
            <hardwareInterface>hardware_interface/EffortJointInterface</hardwareInterface>
        </joint>
        <actuator name="leg_r1_motor">
            <hardwareInterface>hardware_interface/EffortJointInterface</hardwareInterface>
            <mechanicalReduction>1</mechanicalReduction>
        </actuator>
    </transmission>

    <transmission name="leg_r2_tran">
        <type>transmission_interface/SimpleTransmission</type>
        <joint name="leg_r2_joint">
            <hardwareInterface>hardware_interface/EffortJointInterface</hardwareInterface>
        </joint>
        <actuator name="leg_r2_motor">
            <hardwareInterface>hardware_interface/EffortJointInterface</hardwareInterface>
            <mechanicalReduction>1</mechanicalReduction>
        </actuator>
    </transmission>

    <transmission name="leg_r3_tran">
        <type>transmission_interface/SimpleTransmission</type>
        <joint name="leg_r3_joint">
            <hardwareInterface>hardware_interface/EffortJointInterface</hardwareInterface>
        </joint>
        <actuator name="leg_r3_motor">
            <hardwareInterface>hardware_interface/EffortJointInterface</hardwareInterface>
            <mechanicalReduction>1</mechanicalReduction>
        </actuator>
    </transmission>

    <transmission name="leg_r4_tran">
        <type>transmission_interface/SimpleTransmission</type>
        <joint name="leg_r4_joint">
            <hardwareInterface>hardware_interface/EffortJointInterface</hardwareInterface>
        </joint>
        <actuator name="leg_r4_motor">
            <hardwareInterface>hardware_interface/EffortJointInterface</hardwareInterface>
            <mechanicalReduction>1</mechanicalReduction>
        </actuator>
    </transmission>

    <transmission name="leg_r5_tran">
        <type>transmission_interface/SimpleTransmission</type>
        <joint name="leg_r5_joint">
            <hardwareInterface>hardware_interface/EffortJointInterface</hardwareInterface>
        </joint>
        <actuator name="leg_r5_motor">
            <hardwareInterface>hardware_interface/EffortJointInterface</hardwareInterface>
            <mechanicalReduction>1</mechanicalReduction>
        </actuator>
    </transmission>

	<transmission name="leg_r6_tran">
        <type>transmission_interface/SimpleTransmission</type>
        <joint name="leg_r6_joint">
            <hardwareInterface>hardware_interface/EffortJointInterface</hardwareInterface>
        </joint>
        <actuator name="leg_r6_motor">
            <hardwareInterface>hardware_interface/EffortJointInterface</hardwareInterface>
            <mechanicalReduction>1</mechanicalReduction>
        </actuator>
    </transmission>

  
  
  
	<link name="leg_l1_link">
		<inertial>
			<origin xyz="-0.00022626 0.06700617 8.992E-05" rpy="0 0 0" />
			<mass value="0.661" />
			<inertia ixx="0.00018657" ixy="1.9E-07" ixz="1.1E-07" iyy="0.00019782" iyz="2.5E-07" izz="0.00022671" />
		</inertial>
		<visual>
			<origin xyz="0 0 0" rpy="0 0 0" />
			<geometry>
				<mesh filename="package://hi_description/meshes/l_hip_pitch_link.STL" />
			</geometry>
			<material name="">
				<color rgba="0.79216 0.81961 0.93333 1" />
			</material>
		</visual>
		<collision>
			<origin xyz="0 0 0" rpy="0 0 0" />
			<geometry>
				<box size="0.01 0.01 0.01" />
			</geometry>
		</collision>
	</link>
	<joint name="leg_l1_joint" type="revolute">
		<origin xyz="0 0.02875 -0.06425" rpy="0 0 0" />
		<parent link="loin_yaw_link" />
		<child link="leg_l1_link" />
		<axis xyz="0 1 0" />
		<limit lower="-1.25" upper="1.75" effort="36" velocity="21" />
	</joint>

	<link name="leg_l2_link">
		<inertial>
			<origin xyz="0.00051186 -0.000186 -0.06635681" rpy="0 0 0" />
			<mass value="0.54219" />
			<inertia ixx="0.00096867" ixy="4.9E-07" ixz="-2.833E-05" iyy="0.00121705" iyz="-2.83E-06" izz="0.00040399" />
		</inertial>
		<visual>
			<origin xyz="0 0 0" rpy="0 0 0" />
			<geometry>
				<mesh filename="package://hi_description/meshes/l_hip_roll_link.STL" />
			</geometry>
			<material name="">
				<color rgba="0.89804 0.91765 0.92941 1" />
			</material>
		</visual>
		<collision>
			<origin xyz="0 0 0" rpy="0 0 0" />
			<geometry>
				<box size="0.01 0.01 0.01" />
			</geometry>
		</collision>
	</link>
	<joint name="leg_l2_joint" type="revolute">
		<origin xyz="0 0.06875 0" rpy="0 0 0" />
		<parent link="leg_l1_link" />
		<child link="leg_l2_link" />
		<axis xyz="1 0 0" />
		<limit lower="-0.5" upper="0.5" effort="36" velocity="21" />
	</joint>

	<link name="leg_l3_link">
		<inertial>
			<origin xyz="0 -0.0019897 -0.066297" rpy="0 0 0" />
			<mass value="0.23898" />
			<inertia ixx="0.00050536" ixy="0" ixz="0" iyy="0.00032488" iyz="-1.858E-05" izz="0.00029126" />
		</inertial>
		<visual>
			<origin xyz="0 0 0" rpy="0 0 0" />
			<geometry>
				<mesh filename="package://hi_description/meshes/l_thigh_link.STL" />
			</geometry>
			<material name="">
				<color rgba="0.89804 0.91765 0.92941 1" />
			</material>
		</visual>
		<collision>
			<origin xyz="0 0 0" rpy="0 0 0" />
			<geometry>
				<box size="0.01 0.01 0.01" />
			</geometry>
		</collision>
	</link>
	<joint name="leg_l3_joint" type="revolute">
		<origin xyz="0 0 -0.09425" rpy="0 0 0" />
		<parent link="leg_l2_link" />
		<child link="leg_l3_link" />
		<axis xyz="0 0 1" />
		<limit lower="-0.3" upper="0.6" effort="36" velocity="21" />
	</joint>

	<link name="leg_l4_link">
		<inertial>
			<origin xyz="8.965E-05 0.00206794 -0.05065108" rpy="0 0 0" />
			<mass value="1.2" />
			<inertia ixx="0.0068013" ixy="2.6E-07" ixz="3.47E-06" iyy="0.00675095" iyz="4.2E-07" izz="0.00034715" />
		</inertial>
		<visual>
			<origin xyz="0 0 0" rpy="0 0 0" />
			<geometry>
				<mesh filename="package://hi_description/meshes/l_calf_link.STL" />
			</geometry>
			<material name="">
				<color rgba="1 1 1 1" />
			</material>
		</visual>
		<collision>
			<origin xyz="0 0 0" rpy="0 0 0" />
			<geometry>
				<box size="0.01 0.01 0.01" />
			</geometry>
		</collision>
	</link>
	<joint name="leg_l4_joint" type="revolute">
		<origin xyz="0 0 -0.10575" rpy="0 0 0" />
		<parent link="leg_l3_link" />
		<child link="leg_l4_link" />
		<axis xyz="0 1 0" />
		<limit lower="-0.65" upper="1.65" effort="36" velocity="21" />
	</joint>

	<link name="leg_l5_link">
		<inertial>
			<origin xyz="0.00467932 -0.00047699 2.1252E-12" rpy="0 0 0" />
			<mass value="0.16682" />
			<inertia ixx="0.00011981" ixy="-6.4E-07" ixz="-8.1927E-13" iyy="0.00022179" iyz="-3.7346E-17" izz="0.00030766" />
		</inertial>
		<visual>
			<origin xyz="0 0 0" rpy="0 0 0" />
			<geometry>
				<mesh filename="package://hi_description/meshes/l_ankle_pitch_link.STL" />
			</geometry>
			<material name="">
				<color rgba="0.89804 0.91765 0.92941 1" />
			</material>
		</visual>
		<collision>
			<origin xyz="0 0 0" rpy="0 0 0" />
			<geometry>
				<box size="0.01 0.01 0.01" />
			</geometry>
		</collision>
	</link>
	<joint name="leg_l5_joint" type="revolute">
		<origin xyz="0 0 -0.2" rpy="0 0 0" />
		<parent link="leg_l4_link" />
		<child link="leg_l5_link" />
		<axis xyz="0 1 0" />
		<limit lower="-0.9" upper="0.9" effort="36" velocity="21" />
	</joint>

	<link name="leg_l6_link">
		<inertial>
			<origin xyz="-0.03772 9.584E-05 -0.02425" rpy="0 0 0" />
			<mass value="0.5" />
			<inertia ixx="0.0004095" ixy="-2.3E-06" ixz="-0.00012156" iyy="0.00145" iyz="-5.1E-07" izz="0.0013334" />
		</inertial>
		<visual>
			<origin xyz="0 0 0" rpy="0 0 0" />
			<geometry>
				<mesh filename="package://hi_description/meshes/l_ankle_roll_link.STL" />
			</geometry>
			<material name="">
				<color rgba="0.89804 0.91765 0.92941 1" />
			</material>
		</visual>
		<collision>
			<origin xyz="0 0 0" rpy="0 0 0" />
			<geometry>
				<box size="0.01 0.01 0.01" />
			</geometry>
		</collision>
	</link>
	<joint name="leg_l6_joint" type="revolute">
		<origin xyz="0.07525 0.0003 0" rpy="0 0 0" />
		<parent link="leg_l5_link" />
		<child link="leg_l6_link" />
		<axis xyz="1 0 0" />
		<limit lower="-0.8" upper="0.8" effort="36" velocity="21" />
	</joint>

	<joint name="leg_l5_fixed_1" type="fixed">
		<origin xyz="0.03 0.02 -0.0400" rpy="0 0 0" />
		<parent link="leg_l6_link" />
		<child link="leg_l_f1_link" />
	</joint>
	<link name="leg_l_f1_link">
		<inertial>
		<mass value="0.01" />
		<inertia ixx="0.000001" ixy="0" ixz="0" iyy="0.000001" iyz="0" izz="0.000001" />
		</inertial>
		<visual>
		<origin rpy="0 0 0" xyz="0 0 0" />
		<geometry>
			<sphere radius="0.001" />
		</geometry>
		</visual>
		<collision>
		<origin rpy="0 0 0" xyz="0 0 0" />
		<geometry>
			<sphere radius="0.001" />
		</geometry>
		</collision>
	</link>

	<joint name="leg_l5_fixed_2" type="fixed">
		<origin xyz="0.03 -0.02 -0.0400" rpy="0 0 0" />
		<parent link="leg_l6_link" />
		<child link="leg_l_f2_link" />
	</joint>
	<link name="leg_l_f2_link">
		<inertial>
		<mass value="0.01" />
		<inertia ixx="0.000001" ixy="0" ixz="0" iyy="0.000001" iyz="0" izz="0.000001" />
		</inertial>
		<visual>
		<origin rpy="0 0 0" xyz="0 0 0" />
		<geometry>
			<sphere radius="0.001" />
		</geometry>
		</visual>
		<collision>
		<origin rpy="0 0 0" xyz="-0 0 0" />
		<geometry>
			<sphere radius="0.001" />
		</geometry>
		</collision>
	</link>	

	<joint name="leg_l5_fixed_3" type="fixed">
		<origin xyz="-0.12 0.02 -0.0400" rpy="0 0 0" />
		<parent link="leg_l6_link" />
		<child link="leg_l_f3_link" />
	</joint>
	<link name="leg_l_f3_link">
		<inertial>
		<mass value="0.01" />
		<inertia ixx="0.000001" ixy="0" ixz="0" iyy="0.000001" iyz="0" izz="0.000001" />
		</inertial>
		<visual>
		<origin rpy="0 0 0" xyz="0 0 0" />
		<geometry>
			<sphere radius="0.001" />
		</geometry>
		</visual>
		<collision>
		<origin rpy="0 0 0" xyz="0 0 0" />
		<geometry>
			<sphere radius="0.001" />
		</geometry>
		</collision>
	</link>

	<joint name="leg_l5_fixed_4" type="fixed">
		<origin xyz="-0.12 -0.02 -0.0400" rpy="0 0 0" />
		<parent link="leg_l6_link" />
		<child link="leg_l_f4_link" />
	</joint>
	<link name="leg_l_f4_link">
		<inertial>
		<mass value="0.01" />
		<inertia ixx="0.000001" ixy="0" ixz="0" iyy="0.000001" iyz="0" izz="0.000001" />
		</inertial>
		<visual>
		<origin rpy="0 0 0" xyz="0 0 0" />
		<geometry>
			<sphere radius="0.001" />
		</geometry>
		</visual>
		<collision>
		<origin rpy="0 0 0" xyz="-0 0 0" />
		<geometry>
			<sphere radius="0.001" />
		</geometry>
		</collision>
	</link>		

	<gazebo reference="leg_l1_link">
		<mu1>0.6</mu1>
		<mu2>0.6</mu2>
		<self_collide>1</self_collide>
	</gazebo>
	<gazebo reference="leg_l2_link">
		<mu1>0.6</mu1>
		<mu2>0.6</mu2>
		<self_collide>1</self_collide>
	</gazebo>
	<gazebo reference="leg_l3_link">
		<mu1>0.6</mu1>
		<mu2>0.6</mu2>
		<self_collide>1</self_collide>
	</gazebo>
	<gazebo reference="leg_l4_link">
		<mu1>0.6</mu1>
		<mu2>0.6</mu2>
		<self_collide>1</self_collide>
	</gazebo>
	<gazebo reference="leg_l5_link">
		<mu1>0.6</mu1>
		<mu2>0.6</mu2>
		<self_collide>1</self_collide>
	</gazebo>
	<gazebo reference="leg_l6_link">
		<mu1>0.6</mu1>
		<mu2>0.6</mu2>
		<self_collide>1</self_collide>
	</gazebo>
	<gazebo reference="leg_l_f1_link">
		<mu1>3.0</mu1>
		<mu2>3.0</mu2>
		<self_collide>1</self_collide>
		<kp value="1000000.0" />
		<kd value="100.0" />
		<maxVel>1.0</maxVel>
		<minDepth>0.00</minDepth>
	</gazebo>
	<gazebo reference="leg_l_f2_link">
		<mu1>3.0</mu1>
		<mu2>3.0</mu2>
		<self_collide>1</self_collide>
		<kp value="1000000.0" />
		<kd value="100.0" />
		<maxVel>1.0</maxVel>
		<minDepth>0.00</minDepth>
	</gazebo>
	<gazebo reference="leg_l_f3_link">
		<mu1>3.0</mu1>
		<mu2>3.0</mu2>
		<self_collide>1</self_collide>
		<kp value="1000000.0" />
		<kd value="100.0" />
		<maxVel>1.0</maxVel>
		<minDepth>0.00</minDepth>
	</gazebo>
	<gazebo reference="leg_l_f4_link">
		<mu1>3.0</mu1>
		<mu2>3.0</mu2>
		<self_collide>1</self_collide>
		<kp value="1000000.0" />
		<kd value="100.0" />
		<maxVel>1.0</maxVel>
		<minDepth>0.00</minDepth>
	</gazebo>

	<transmission name="leg_l1_tran">
		<type>transmission_interface/SimpleTransmission</type>
		<joint name="leg_l1_joint">
			<hardwareInterface>hardware_interface/EffortJointInterface</hardwareInterface>
		</joint>
		<actuator name="leg_l1_motor">
			<hardwareInterface>hardware_interface/EffortJointInterface</hardwareInterface>
			<mechanicalReduction>1</mechanicalReduction>
		</actuator>
	</transmission>

	<transmission name="leg_l2_tran">
		<type>transmission_interface/SimpleTransmission</type>
		<joint name="leg_l2_joint">
			<hardwareInterface>hardware_interface/EffortJointInterface</hardwareInterface>
		</joint>
		<actuator name="leg_l2_motor">
			<hardwareInterface>hardware_interface/EffortJointInterface</hardwareInterface>
			<mechanicalReduction>1</mechanicalReduction>
		</actuator>
	</transmission>

	<transmission name="leg_l3_tran">
		<type>transmission_interface/SimpleTransmission</type>
		<joint name="leg_l3_joint">
			<hardwareInterface>hardware_interface/EffortJointInterface</hardwareInterface>
		</joint>
		<actuator name="leg_l3_motor">
			<hardwareInterface>hardware_interface/EffortJointInterface</hardwareInterface>
			<mechanicalReduction>1</mechanicalReduction>
		</actuator>
	</transmission>

	<transmission name="leg_l4_tran">
		<type>transmission_interface/SimpleTransmission</type>
		<joint name="leg_l4_joint">
			<hardwareInterface>hardware_interface/EffortJointInterface</hardwareInterface>
		</joint>
		<actuator name="leg_l4_motor">
			<hardwareInterface>hardware_interface/EffortJointInterface</hardwareInterface>
			<mechanicalReduction>1</mechanicalReduction>
		</actuator>
	</transmission>

	<transmission name="leg_l5_tran">
		<type>transmission_interface/SimpleTransmission</type>
		<joint name="leg_l5_joint">
			<hardwareInterface>hardware_interface/EffortJointInterface</hardwareInterface>
		</joint>
		<actuator name="leg_l5_motor">
			<hardwareInterface>hardware_interface/EffortJointInterface</hardwareInterface>
			<mechanicalReduction>1</mechanicalReduction>
		</actuator>
	</transmission>

	<transmission name="leg_l6_tran">
		<type>transmission_interface/SimpleTransmission</type>
		<joint name="leg_l6_joint">
			<hardwareInterface>hardware_interface/EffortJointInterface</hardwareInterface>
		</joint>
		<actuator name="leg_l6_motor">
			<hardwareInterface>hardware_interface/EffortJointInterface</hardwareInterface>
			<mechanicalReduction>1</mechanicalReduction>
		</actuator>
	</transmission>		
</robot>